<?xml version="1.0" ?>
<!-- =================================================================================== -->
<!-- |    This document was autogenerated by xacro from /home/andreas/dev_ws/kumi_stack/src/kumi_description/urdf/kumi.xacro | -->
<!-- |    EDITING THIS FILE BY HAND IS NOT RECOMMENDED                                 | -->
<!-- =================================================================================== -->
<robot name="kumi">
  <ros2_control name="KumiHardware" type="system">
    <hardware>
      <plugin>gz_ros2_control/GazeboSimSystem</plugin>
    </hardware>
    <joint name="front_sh">
      <command_interface name="position"/>
      <state_interface name="position"/>
      <state_interface name="velocity"/>
    </joint>
    <joint name="front_ank_y">
      <command_interface name="position"/>
      <state_interface name="position"/>
      <state_interface name="velocity"/>
    </joint>
    <joint name="front_ank_z">
      <command_interface name="position"/>
      <state_interface name="position"/>
      <state_interface name="velocity"/>
    </joint>
    <joint name="rear_sh">
      <command_interface name="position"/>
      <state_interface name="position"/>
      <state_interface name="velocity"/>
    </joint>
    <joint name="rear_ank_y">
      <command_interface name="position"/>
      <state_interface name="position"/>
      <state_interface name="velocity"/>
    </joint>
    <joint name="rear_ank_z">
      <command_interface name="position"/>
      <state_interface name="position"/>
      <state_interface name="velocity"/>
    </joint>
  </ros2_control>
  <gazebo>
    <plugin filename="gz_ros2_control-system" name="gz_ros2_control::GazeboSimROS2ControlPlugin">
      <parameters>/home/andreas/dev_ws/kumi_stack/install/kumi_control/share/kumi_control/config/trajectory_control_config.yaml</parameters>
    </plugin>
  </gazebo>
  <link name="body">
    <visual>
      <origin rpy="0 0 0" xyz="0 0 0"/>
      <geometry>
        <mesh filename="file:///home/andreas/dev_ws/kumi_stack/install/kumi_description/share/kumi_description/meshes/body_v5.STL" scale="0.001 0.001 0.001"/>
      </geometry>
      <material name="gray">
        <color rgba="0 0 0 0.8"/>
      </material>
    </visual>
    <collision>
      <origin rpy="0 0 0" xyz="0 0 0"/>
      <geometry>
        <mesh filename="file:///home/andreas/dev_ws/kumi_stack/install/kumi_description/share/kumi_description/meshes/body_v5.STL" scale="0.001 0.001 0.001"/>
      </geometry>
    </collision>
    <inertial>
      <origin rpy="0 0 0" xyz="0 0 0"/>
      <mass value="0.15"/>
      <inertia ixx="0.000226" ixy="0.0" ixz="0.0" iyy="0.000755" iyz="0.0" izz="0.000971"/>
    </inertial>
  </link>
  <joint name="front_sh" type="revolute">
    <origin rpy="0 0 0" xyz="-0.09 -0.006 0"/>
    <parent link="body"/>
    <child link="front_leg"/>
    <axis xyz="0 -1 0"/>
    <limit effort="1000" lower="-6.283185307179586" upper="6.283185307179586" velocity="5"/>
    <dynamics damping="0.5" friction="0.2"/>
  </joint>
  <gazebo reference="front_sh">
    <sensor name="front_sh_force_torque" type="force_torque">
      <always_on>true</always_on>
      <update_rate>500</update_rate>
      <force_torque>
        <frame>child</frame>
        <measure_direction>child_to_parent</measure_direction>
      </force_torque>
    </sensor>
  </gazebo>
  <link name="front_leg">
    <visual>
      <origin rpy="0 -1.5707963267948966 0" xyz="0 0 0"/>
      <geometry>
        <mesh filename="file:///home/andreas/dev_ws/kumi_stack/install/kumi_description/share/kumi_description/meshes/leg_v2.stl" scale="0.001 0.001 0.001"/>
      </geometry>
      <material name="gray">
        <color rgba="0 0 0 0.8"/>
      </material>
    </visual>
    <collision>
      <origin rpy="0 -1.5707963267948966 0" xyz="0 0 0"/>
      <geometry>
        <mesh filename="file:///home/andreas/dev_ws/kumi_stack/install/kumi_description/share/kumi_description/meshes/leg_v2.stl" scale="0.001 0.001 0.001"/>
      </geometry>
    </collision>
    <inertial>
      <origin rpy="0 -1.5707963267948966 0" xyz="0 0 0"/>
      <mass value="0.3"/>
      <inertia ixx="0.000023773" ixy="0.0" ixz="0.0" iyy="0.000513246" iyz="0.0" izz="0.000524232"/>
    </inertial>
  </link>
  <joint name="realsense_joint" type="fixed">
    <origin rpy="0 0 0" xyz="0 0 0"/>
    <parent link="front_leg"/>
    <child link="realsense"/>
  </joint>
  <link name="realsense">
    <visual>
      <origin rpy="1.5707963267948966 0  -1.5707963267948966" xyz="-0.025 0 -0.057"/>
      <geometry>
        <mesh filename="file:///home/andreas/dev_ws/kumi_stack/install/kumi_description/share/kumi_description/meshes/realsense.stl" scale="0.001 0.001 0.001"/>
      </geometry>
      <material name="green">
        <color rgba="0 1 0 1"/>
      </material>
    </visual>
    <collision>
      <origin rpy="1.5707963267948966 0  -1.5707963267948966" xyz="-0.025 0 -0.057"/>
      <geometry>
        <mesh filename="file:///home/andreas/dev_ws/kumi_stack/install/kumi_description/share/kumi_description/meshes/realsense.stl" scale="0.001 0.001 0.001"/>
      </geometry>
    </collision>
    <inertial>
      <origin rpy="1.5707963267948966 0  -1.5707963267948966" xyz="-0.025 0 -0.057"/>
      <mass value="0.005"/>
      <inertia ixx="0.000091" ixy="0.0" ixz="0.0" iyy="0.000165" iyz="0.0" izz="0.000091"/>
    </inertial>
  </link>
  <gazebo reference="realsense">
    <sensor name="realsense" type="rgbd_camera">
      <pose>-0.025 0 -0.057 0 0 3.14159</pose>
      <always_on>1</always_on>
      <update_rate>100</update_rate>
      <topic>/d435_rgbd</topic>
      <frameName>realsense</frameName>
      <camera name="rs_front">
        <horizontal_fov>1.50098</horizontal_fov>
        <lens>
          <intrinsics>
            <fx>343.159</fx>
            <fy>343.159</fy>
            <cx>319.5</cx>
            <cy>179.5</cy>
            <s>0</s>
          </intrinsics>
        </lens>
        <distortion>
          <k1>0.0</k1>
          <k2>0.0</k2>
          <k3>0.0</k3>
          <p1>0.0</p1>
          <p2>0.0</p2>
          <center>0.5 0.5</center>
        </distortion>
        <image>
          <width>640</width>
          <height>360</height>
          <format>R8G8B8</format>
        </image>
        <clip>
          <near>0.01</near>
          <far>300</far>
        </clip>
        <depth_camera>
          <clip>
            <near>0.1</near>
            <far>10</far>
          </clip>
        </depth_camera>
        <noise>
          <type>gaussian</type>
          <mean>0</mean>
          <stddev>0.007</stddev>
        </noise>
      </camera>
    </sensor>
  </gazebo>
  <joint name="front_ank_y" type="revolute">
    <origin rpy="0 0 0" xyz="0 0 -0.11"/>
    <parent link="front_leg"/>
    <child link="front_foot_dummy"/>
    <axis xyz="0 -1 0"/>
    <limit effort="1000" lower="-6.283185307179586" upper="6.283185307179586" velocity="5"/>
    <dynamics damping="0.1" friction="0.2"/>
  </joint>
  <gazebo reference="front_ank_y">
    <sensor name="front_ank_force_torque" type="force_torque">
      <always_on>true</always_on>
      <update_rate>500</update_rate>
      <force_torque>
        <frame>child</frame>
        <measure_direction>child_to_parent</measure_direction>
      </force_torque>
    </sensor>
  </gazebo>
  <link name="front_foot_dummy">
    <inertial>
      <origin rpy="0 0 0" xyz="0 0 0"/>
      <mass value="0.001"/>
      <inertia ixx="1e-5" ixy="0" ixz="0" iyy="1e-5" iyz="0" izz="1e-5"/>
    </inertial>
  </link>
  <joint name="front_ank_z" type="revolute">
    <origin rpy="0 0 0" xyz="0 0 0"/>
    <parent link="front_foot_dummy"/>
    <child link="front_foot"/>
    <axis xyz="0 0 1"/>
    <limit effort="1000" lower="-0.3141592653589793" upper="0.3141592653589793" velocity="5"/>
    <dynamics damping="0.1" friction="0.2"/>
  </joint>
  <gazebo reference="front_ank_z">
    <sensor name="front_ank_force_torque" type="force_torque">
      <always_on>true</always_on>
      <update_rate>500</update_rate>
      <force_torque>
        <frame>child</frame>
        <measure_direction>child_to_parent</measure_direction>
      </force_torque>
    </sensor>
  </gazebo>
  <link name="front_foot">
    <visual>
      <origin rpy="1.5707963267948966 0  -1.5707963267948966" xyz="0 -0.007 0"/>
      <geometry>
        <mesh filename="file:///home/andreas/dev_ws/kumi_stack/install/kumi_description/share/kumi_description/meshes/piedino_v3.STL" scale="0.001 0.001 0.001"/>
      </geometry>
      <material name="green">
        <color rgba="0 1 0 0.8"/>
      </material>
    </visual>
    <collision name="frontFootCollision">
      <origin rpy="1.5707963267948966 0  -1.5707963267948966" xyz="0 0 0"/>
      <geometry>
        <mesh filename="file:///home/andreas/dev_ws/kumi_stack/install/kumi_description/share/kumi_description/meshes/piedino_v3.STL" scale="0.001 0.001 0.001"/>
      </geometry>
    </collision>
    <inertial>
      <origin rpy="1.5707963267948966 0  -1.5707963267948966" xyz="0 0 0"/>
      <mass value="0.15"/>
      <inertia ixx="0.000091" ixy="0.0" ixz="0.0" iyy="0.000165" iyz="0.0" izz="0.000091"/>
    </inertial>
  </link>
  <joint name="rear_sh" type="revolute">
    <origin rpy="0 0 0" xyz="0.09 0.006 0"/>
    <parent link="body"/>
    <child link="rear_leg"/>
    <axis xyz="0 1 0"/>
    <limit effort="1000" lower="-6.283185307179586" upper="6.283185307179586" velocity="5"/>
    <dynamics damping="0.5" friction="0.2"/>
  </joint>
  <gazebo reference="rear_sh">
    <sensor name="rear_sh_force_torque" type="force_torque">
      <always_on>true</always_on>
      <update_rate>500</update_rate>
      <force_torque>
        <frame>child</frame>
        <measure_direction>child_to_parent</measure_direction>
      </force_torque>
    </sensor>
  </gazebo>
  <link name="rear_leg">
    <visual>
      <origin rpy="0 -1.5707963267948966 3.141592653589793" xyz="0 0 0"/>
      <geometry>
        <mesh filename="file:///home/andreas/dev_ws/kumi_stack/install/kumi_description/share/kumi_description/meshes/leg_v2.stl" scale="0.001 0.001 0.001"/>
      </geometry>
      <material name="gray">
        <color rgba="0 0 0 0.8"/>
      </material>
    </visual>
    <collision>
      <origin rpy="0 -1.5707963267948966 3.141592653589793" xyz="0 0 0"/>
      <geometry>
        <mesh filename="file:///home/andreas/dev_ws/kumi_stack/install/kumi_description/share/kumi_description/meshes/leg_v2.stl" scale="0.001 0.001 0.001"/>
      </geometry>
    </collision>
    <inertial>
      <origin rpy="0 -1.5707963267948966 3.141592653589793" xyz="0 0 0"/>
      <mass value="0.3"/>
      <inertia ixx="0.000023773" ixy="0.0" ixz="0.0" iyy="0.000513246" iyz="0.0" izz="0.000524232"/>
    </inertial>
  </link>
  <joint name="rear_ank_y" type="revolute">
    <origin rpy="0 0 0" xyz="0 0 -0.11"/>
    <parent link="rear_leg"/>
    <child link="rear_foot_dummy"/>
    <axis xyz="0 1 0"/>
    <limit effort="1000" lower="-6.283185307179586" upper="6.283185307179586" velocity="5"/>
    <dynamics damping="0.1" friction="0.2"/>
  </joint>
  <gazebo reference="rear_ank_y">
    <sensor name="rear_ank_force_torque" type="force_torque">
      <always_on>true</always_on>
      <update_rate>500</update_rate>
      <force_torque>
        <frame>child</frame>
        <measure_direction>child_to_parent</measure_direction>
      </force_torque>
    </sensor>
  </gazebo>
  <link name="rear_foot_dummy">
    <inertial>
      <origin rpy="0 0 0" xyz="0 0 0"/>
      <mass value="0.001"/>
      <inertia ixx="1e-5" ixy="0" ixz="0" iyy="1e-5" iyz="0" izz="1e-5"/>
    </inertial>
  </link>
  <joint name="rear_ank_z" type="revolute">
    <origin rpy="0 0 0" xyz="0 0 0"/>
    <parent link="rear_foot_dummy"/>
    <child link="rear_foot"/>
    <axis xyz="0 0 1"/>
    <limit effort="1000" lower="-0.3141592653589793" upper="0.3141592653589793" velocity="5"/>
    <dynamics damping="0.1" friction="0.2"/>
  </joint>
  <gazebo reference="rear_ank_z">
    <sensor name="front_ank_force_torque" type="force_torque">
      <always_on>true</always_on>
      <update_rate>500</update_rate>
      <force_torque>
        <frame>child</frame>
        <measure_direction>child_to_parent</measure_direction>
      </force_torque>
    </sensor>
  </gazebo>
  <link name="rear_foot">
    <visual>
      <origin rpy="1.5707963267948966 0  1.5707963267948966" xyz="0 0.007 0"/>
      <geometry>
        <mesh filename="file:///home/andreas/dev_ws/kumi_stack/install/kumi_description/share/kumi_description/meshes/piedino_v3.STL" scale="0.001 0.001 0.001"/>
      </geometry>
      <material name="red">
        <color rgba="1 0 0 0.8"/>
      </material>
    </visual>
    <collision name="rearFootCollision">
      <origin rpy="1.5707963267948966 0  1.5707963267948966" xyz="0 0 0"/>
      <geometry>
        <mesh filename="file:///home/andreas/dev_ws/kumi_stack/install/kumi_description/share/kumi_description/meshes/piedino_v3.STL" scale="0.001 0.001 0.001"/>
      </geometry>
    </collision>
    <inertial>
      <origin rpy="1.5707963267948966 0  1.5707963267948966" xyz="0 0 0"/>
      <mass value="0.15"/>
      <inertia ixx="0.000091" ixy="0.0" ixz="0.0" iyy="0.000165" iyz="0.0" izz="0.000091"/>
    </inertial>
  </link>
</robot>
